Workbook

Sheet Резюме
A1: SCANDIC — рынок Шымкента: розница и региональные дилеры | B1: SCANDIC — рынок Шымкента: розница и региональные дилеры | C1: SCANDIC — рынок Шымкента: розница и региональные дилеры | D1: SCANDIC — рынок Шымкента: розница и региональные дилеры | E1: SCANDIC — рынок Шымкента: розница и региональные дилеры | F1: SCANDIC — рынок Шымкента: розница и региональные дилеры | G1: SCANDIC — рынок Шымкента: розница и региональные дилеры | H1: SCANDIC — рынок Шымкента: розница и региональные дилеры | I1: SCANDIC — рынок Шымкента: розница и региональные дилеры | J1: SCANDIC — рынок Шымкента: розница и региональные дилеры | K1: SCANDIC — рынок Шымкента: розница и региональные дилеры | L1: SCANDIC — рынок Шымкента: розница и региональные дилеры
A2: SCANDIC — рынок Шымкента: розница и региональные дилеры | B2: SCANDIC — рынок Шымкента: розница и региональные дилеры | C2: SCANDIC — рынок Шымкента: розница и региональные дилеры | D2: SCANDIC — рынок Шымкента: розница и региональные дилеры | E2: SCANDIC — рынок Шымкента: розница и региональные дилеры | F2: SCANDIC — рынок Шымкента: розница и региональные дилеры | G2: SCANDIC — рынок Шымкента: розница и региональные дилеры | H2: SCANDIC — рынок Шымкента: розница и региональные дилеры | I2: SCANDIC — рынок Шымкента: розница и региональные дилеры | J2: SCANDIC — рынок Шымкента: розница и региональные дилеры | K2: SCANDIC — рынок Шымкента: розница и региональные дилеры | L2: SCANDIC — рынок Шымкента: розница и региональные дилеры
A3: Best-effort исследование по открытым источникам · дата проверки 11.08.2026 · значения компаний отмечены как self-reported | B3: Best-effort исследование по открытым источникам · дата проверки 11.08.2026 · значения компаний отмечены как self-reported | C3: Best-effort исследование по открытым источникам · дата проверки 11.08.2026 · значения компаний отмечены как self-reported | D3: Best-effort исследование по открытым источникам · дата проверки 11.08.2026 · значения компаний отмечены как self-reported | E3: Best-effort исследование по открытым источникам · дата проверки 11.08.2026 · значения компаний отмечены как self-reported | F3: Best-effort исследование по открытым источникам · дата проверки 11.08.2026 · значения компаний отмечены как self-reported | G3: Best-effort исследование по открытым источникам · дата проверки 11.08.2026 · значения компаний отмечены как self-reported | H3: Best-effort исследование по открытым источникам · дата проверки 11.08.2026 · значения компаний отмечены как self-reported | I3: Best-effort исследование по открытым источникам · дата проверки 11.08.2026 · значения компаний отмечены как self-reported | J3: Best-effort исследование по открытым источникам · дата проверки 11.08.2026 · значения компаний отмечены как self-reported | K3: Best-effort исследование по открытым источникам · дата проверки 11.08.2026 · значения компаний отмечены как self-reported | L3: Best-effort исследование по открытым источникам · дата проверки 11.08.2026 · значения компаний отмечены как self-reported
A5: Именная база точек | B5: Именная база точек | C5: Именная база точек | D5: Организации / бренды | E5: Организации / бренды | F5: Организации / бренды | G5: Проверенные дилеры | H5: Проверенные дилеры | I5: Проверенные дилеры | J5: Дилеры рейтинга A | K5: Дилеры рейтинга A | L5: Дилеры рейтинга A
A6: =COUNTA('Торговые точки'!$A$2:$A$846) -> 845 | D6: =COUNTA('Компании и сети'!$A$2:$A$570) -> 569 | G6: =COUNTA(Дилеры!$A$2:$A$22) -> 21 | J6: =COUNTIF(Дилеры!$D$2:$D$22,"A") -> 9
A9: АЗС + АГЗС в базе | B9: АЗС + АГЗС в базе | C9: АЗС + АГЗС в базе | D9: Вся розница: потолок | E9: Вся розница: потолок | F9: Вся розница: потолок | G9: Скрининг: нижняя граница | H9: Скрининг: нижняя граница | I9: Скрининг: нижняя граница | J9: Скрининг: верхняя граница | K9: Скрининг: верхняя граница | L9: Скрининг: верхняя граница
A10: =COUNTIF('Торговые точки'!$E$2:$E$846,"АЗС")+COUNTIF('Торговые точки'!$E$2:$E$846,"АГЗС/ГАЗС") -> 206 | D10: ='Оценка рынка'!$B$7 -> 4962 | G10: ='Оценка рынка'!$B$20 -> 1172 | J10: ='Оценка рынка'!$B$21 -> 2769
A13: Вывод: адресная база содержит 845 кандидатов, но реальное число пригодных точек публично не измерено. Защищаемый до полевого аудита ориентир — 1,2–2,8 тыс. форматно близких объектов; это не SAM. Широкий потолок всей розницы — 4 962. | B13: Вывод: адресная база содержит 845 кандидатов, но реальное число пригодных точек публично не измерено. Защищаемый до полевого аудита ориентир — 1,2–2,8 тыс. форматно близких объектов; это не SAM. Широкий потолок всей розницы — 4 962. | C13: Вывод: адресная база содержит 845 кандидатов, но реальное число пригодных точек публично не измерено. Защищаемый до полевого аудита ориентир — 1,2–2,8 тыс. форматно близких объектов; это не SAM. Широкий потолок всей розницы — 4 962. | D13: Вывод: адресная база содержит 845 кандидатов, но реальное число пригодных точек публично не измерено. Защищаемый до полевого аудита ориентир — 1,2–2,8 тыс. форматно близких объектов; это не SAM. Широкий потолок всей розницы — 4 962. | E13: Вывод: адресная база содержит 845 кандидатов, но реальное число пригодных точек публично не измерено. Защищаемый до полевого аудита ориентир — 1,2–2,8 тыс. форматно близких объектов; это не SAM. Широкий потолок всей розницы — 4 962. | F13: Вывод: адресная база содержит 845 кандидатов, но реальное число пригодных точек публично не измерено. Защищаемый до полевого аудита ориентир — 1,2–2,8 тыс. форматно близких объектов; это не SAM. Широкий потолок всей розницы — 4 962. | G13: Вывод: адресная база содержит 845 кандидатов, но реальное число пригодных точек публично не измерено. Защищаемый до полевого аудита ориентир — 1,2–2,8 тыс. форматно близких объектов; это не SAM. Широкий потолок всей розницы — 4 962. | H13: Вывод: адресная база содержит 845 кандидатов, но реальное число пригодных точек публично не измерено. Защищаемый до полевого аудита ориентир — 1,2–2,8 тыс. форматно близких объектов; это не SAM. Широкий потолок всей розницы — 4 962. | I13: Вывод: адресная база содержит 845 кандидатов, но реальное число пригодных точек публично не измерено. Защищаемый до полевого аудита ориентир — 1,2–2,8 тыс. форматно близких объектов; это не SAM. Широкий потолок всей розницы — 4 962. | J13: Вывод: адресная база содержит 845 кандидатов, но реальное число пригодных точек публично не измерено. Защищаемый до полевого аудита ориентир — 1,2–2,8 тыс. форматно близких объектов; это не SAM. Широкий потолок всей розницы — 4 962. | K13: Вывод: адресная база содержит 845 кандидатов, но реальное число пригодных точек публично не измерено. Защищаемый до полевого аудита ориентир — 1,2–2,8 тыс. форматно близких объектов; это не SAM. Широкий потолок всей розницы — 4 962. | L13: Вывод: адресная база содержит 845 кандидатов, но реальное число пригодных точек публично не измерено. Защищаемый до полевого аудита ориентир — 1,2–2,8 тыс. форматно близких объектов; это не SAM. Широкий потолок всей розницы — 4 962.
A14: Вывод: адресная база содержит 845 кандидатов, но реальное число пригодных точек публично не измерено. Защищаемый до полевого аудита ориентир — 1,2–2,8 тыс. форматно близких объектов; это не SAM. Широкий потолок всей розницы — 4 962. | B14: Вывод: адресная база содержит 845 кандидатов, но реальное число пригодных точек публично не измерено. Защищаемый до полевого аудита ориентир — 1,2–2,8 тыс. форматно близких объектов; это не SAM. Широкий потолок всей розницы — 4 962. | C14: Вывод: адресная база содержит 845 кандидатов, но реальное число пригодных точек публично не измерено. Защищаемый до полевого аудита ориентир — 1,2–2,8 тыс. форматно близких объектов; это не SAM. Широкий потолок всей розницы — 4 962. | D14: Вывод: адресная база содержит 845 кандидатов, но реальное число пригодных точек публично не измерено. Защищаемый до полевого аудита ориентир — 1,2–2,8 тыс. форматно близких объектов; это не SAM. Широкий потолок всей розницы — 4 962. | E14: Вывод: адресная база содержит 845 кандидатов, но реальное число пригодных точек публично не измерено. Защищаемый до полевого аудита ориентир — 1,2–2,8 тыс. форматно близких объектов; это не SAM. Широкий потолок всей розницы — 4 962. | F14: Вывод: адресная база содержит 845 кандидатов, но реальное число пригодных точек публично не измерено. Защищаемый до полевого аудита ориентир — 1,2–2,8 тыс. форматно близких объектов; это не SAM. Широкий потолок всей розницы — 4 962. | G14: Вывод: адресная база содержит 845 кандидатов, но реальное число пригодных точек публично не измерено. Защищаемый до полевого аудита ориентир — 1,2–2,8 тыс. форматно близких объектов; это не SAM. Широкий потолок всей розницы — 4 962. | H14: Вывод: адресная база содержит 845 кандидатов, но реальное число пригодных точек публично не измерено. Защищаемый до полевого аудита ориентир — 1,2–2,8 тыс. форматно близких объектов; это не SAM. Широкий потолок всей розницы — 4 962. | I14: Вывод: адресная база содержит 845 кандидатов, но реальное число пригодных точек публично не измерено. Защищаемый до полевого аудита ориентир — 1,2–2,8 тыс. форматно близких объектов; это не SAM. Широкий потолок всей розницы — 4 962. | J14: Вывод: адресная база содержит 845 кандидатов, но реальное число пригодных точек публично не измерено. Защищаемый до полевого аудита ориентир — 1,2–2,8 тыс. форматно близких объектов; это не SAM. Широкий потолок всей розницы — 4 962. | K14: Вывод: адресная база содержит 845 кандидатов, но реальное число пригодных точек публично не измерено. Защищаемый до полевого аудита ориентир — 1,2–2,8 тыс. форматно близких объектов; это не SAM. Широкий потолок всей розницы — 4 962. | L14: Вывод: адресная база содержит 845 кандидатов, но реальное число пригодных точек публично не измерено. Защищаемый до полевого аудита ориентир — 1,2–2,8 тыс. форматно близких объектов; это не SAM. Широкий потолок всей розницы — 4 962.
A15: Вывод: адресная база содержит 845 кандидатов, но реальное число пригодных точек публично не измерено. Защищаемый до полевого аудита ориентир — 1,2–2,8 тыс. форматно близких объектов; это не SAM. Широкий потолок всей розницы — 4 962. | B15: Вывод: адресная база содержит 845 кандидатов, но реальное число пригодных точек публично не измерено. Защищаемый до полевого аудита ориентир — 1,2–2,8 тыс. форматно близких объектов; это не SAM. Широкий потолок всей розницы — 4 962. | C15: Вывод: адресная база содержит 845 кандидатов, но реальное число пригодных точек публично не измерено. Защищаемый до полевого аудита ориентир — 1,2–2,8 тыс. форматно близких объектов; это не SAM. Широкий потолок всей розницы — 4 962. | D15: Вывод: адресная база содержит 845 кандидатов, но реальное число пригодных точек публично не измерено. Защищаемый до полевого аудита ориентир — 1,2–2,8 тыс. форматно близких объектов; это не SAM. Широкий потолок всей розницы — 4 962. | E15: Вывод: адресная база содержит 845 кандидатов, но реальное число пригодных точек публично не измерено. Защищаемый до полевого аудита ориентир — 1,2–2,8 тыс. форматно близких объектов; это не SAM. Широкий потолок всей розницы — 4 962. | F15: Вывод: адресная база содержит 845 кандидатов, но реальное число пригодных точек публично не измерено. Защищаемый до полевого аудита ориентир — 1,2–2,8 тыс. форматно близких объектов; это не SAM. Широкий потолок всей розницы — 4 962. | G15: Вывод: адресная база содержит 845 кандидатов, но реальное число пригодных точек публично не измерено. Защищаемый до полевого аудита ориентир — 1,2–2,8 тыс. форматно близких объектов; это не SAM. Широкий потолок всей розницы — 4 962. | H15: Вывод: адресная база содержит 845 кандидатов, но реальное число пригодных точек публично не измерено. Защищаемый до полевого аудита ориентир — 1,2–2,8 тыс. форматно близких объектов; это не SAM. Широкий потолок всей розницы — 4 962. | I15: Вывод: адресная база содержит 845 кандидатов, но реальное число пригодных точек публично не измерено. Защищаемый до полевого аудита ориентир — 1,2–2,8 тыс. форматно близких объектов; это не SAM. Широкий потолок всей розницы — 4 962. | J15: Вывод: адресная база содержит 845 кандидатов, но реальное число пригодных точек публично не измерено. Защищаемый до полевого аудита ориентир — 1,2–2,8 тыс. форматно близких объектов; это не SAM. Широкий потолок всей розницы — 4 962. | K15: Вывод: адресная база содержит 845 кандидатов, но реальное число пригодных точек публично не измерено. Защищаемый до полевого аудита ориентир — 1,2–2,8 тыс. форматно близких объектов; это не SAM. Широкий потолок всей розницы — 4 962. | L15: Вывод: адресная база содержит 845 кандидатов, но реальное число пригодных точек публично не измерено. Защищаемый до полевого аудита ориентир — 1,2–2,8 тыс. форматно близких объектов; это не SAM. Широкий потолок всей розницы — 4 962.
A17: 10 лучших потенциальных дилеров | B17: 10 лучших потенциальных дилеров | C17: 10 лучших потенциальных дилеров | D17: 10 лучших потенциальных дилеров | E17: 10 лучших потенциальных дилеров | F17: 10 лучших потенциальных дилеров | G17: 10 лучших потенциальных дилеров | H17: 10 лучших потенциальных дилеров | I17: 10 лучших потенциальных дилеров | J17: 10 лучших потенциальных дилеров | K17: 10 лучших потенциальных дилеров | L17: 10 лучших потенциальных дилеров
A18: № | B18: Дилер | D18: Рейтинг | E18: Почему подходит | K18: Контакт
A19: =Дилеры!E2 -> 1 | B19: =Дилеры!B2 -> Beverage Trade / FBS Group | D19: =Дилеры!D2 -> A | E19: =Дилеры!F2 -> Самый прозрачный локальный охват: южный хаб, склад 8 000 м² и 4 400 активных точек в четырёх южных городах; для Шымкента отдельно ранее раскрывалось 2 971. | K19: =Дилеры!N2 -> +7 700 090 00 22
A20: =Дилеры!E3 -> 2 | B20: =Дилеры!B3 -> Dudar | D20: =Дилеры!D3 -> A | E20: =Дилеры!F3 -> 18 складов, собственная доставка за 24 часа, полевые coverage-планы и клиентская база от магазинов до АЗС. | K20: =Дилеры!N3 -> +7 701 027-83-47
A21: =Дилеры!E4 -> 3 | B21: =Дилеры!B4 -> Prima Distribution | D21: =Дилеры!D4 -> A | E21: =Дилеры!F4 -> Филиал и прямой контакт в Шымкенте; 35 000+ точек по Казахстану, сильная торговая и мерчендайзинговая система. | K21: =Дилеры!N4 -> +7 777 005 73 00, 8 8000 80 80 81
A22: =Дилеры!E5 -> 4 | B22: =Дилеры!B5 -> Apple City Corps | D22: =Дилеры!D5 -> A | E22: =Дилеры!F5 -> 35 представительств, 27 000+ клиентов, собственные склады и автопарк; шымкентский филиал подтверждён. | K22: =Дилеры!N5 -> +7 727 250 05 50
A23: =Дилеры!E6 -> 5 | B23: =Дилеры!B6 -> Aspan Asia | D23: =Дилеры!D6 -> A | E23: =Дилеры!F6 -> Сильный южный контур, собственные склады/доставка и релевантный импульсный портфель снеков, печенья и напитков. | K23: =Дилеры!N6 -> +7 727 398 04 62, +7 777 191 01 11, +7 777 077 71 13
A24: =Дилеры!E7 -> 6 | B24: =Дилеры!B7 -> ALIDI Kazakhstan | D24: =Дилеры!D7 -> A | E24: =Дилеры!F7 -> Системный route-to-market, доставка MT/GT, локальные торговые представители и 16 000+ точек по Казахстану. | K24: =Дилеры!N7 -> 8 800 080 01 25
A25: =Дилеры!E8 -> 7 | B25: =Дилеры!B8 -> F-Food | D25: =Дилеры!D8 -> A | E25: =Дилеры!F8 -> Шымкентская база 2 500 м², кондитерка и снеки, доставка и действующая региональная дилерская сеть. | K25: =Дилеры!N8 -> +7 7252 98 21 52, +7 778 463 83 73
A26: =Дилеры!E9 -> 8 | B26: =Дилеры!B9 -> BGT Company | D26: =Дилеры!D9 -> A | E26: =Дилеры!F9 -> Локальная клиентская база 3 087, три склада и девять автомобилей — хороший кандидат для быстрого пилота. | K26: =Дилеры!N9 -> 0
A27: =Дилеры!E10 -> 9 | B27: =Дилеры!B10 -> RG Brands Kazakhstan | D27: =Дилеры!D10 -> A | E27: =Дилеры!F10 -> Склад и торговая команда в Шымкенте, плотный охват напитков; ключевой риск — готовность брать внешний бренд. | K27: =Дилеры!N10 -> +7 705 997 05 49
A28: =Дилеры!E11 -> 10 | B28: =Дилеры!B11 -> Star Brands Asia | D28: =Дилеры!D11 -> B | E28: =Дилеры!F11 -> Импульсный портфель снеков и кондитерки, 21 филиал и локальный торговый представитель; требуется подтвердить склад и SLA. | K28: =Дилеры!N11 -> +7 727 382 19 45
A30: Тип точки | B30: Количество | D30: Рейтинг | E30: Дилеры
A31: Магазин у дома / convenience | B31: =COUNTIF('Торговые точки'!$E$2:$E$846,A31) -> 317 | D31: A | E31: =COUNTIF(Дилеры!$D$2:$D$22,D31) -> 9
A32: Супермаркет | B32: =COUNTIF('Торговые точки'!$E$2:$E$846,A32) -> 223 | D32: B | E32: =COUNTIF(Дилеры!$D$2:$D$22,D32) -> 5
A33: АЗС | B33: =COUNTIF('Торговые точки'!$E$2:$E$846,A33) -> 157 | D33: C | E33: =COUNTIF(Дилеры!$D$2:$D$22,D33) -> 7
A34: АГЗС/ГАЗС | B34: =COUNTIF('Торговые точки'!$E$2:$E$846,A34) -> 49
A35: Продуктовый магазин | B35: =COUNTIF('Торговые точки'!$E$2:$E$846,A35) -> 38
A36: Рынок / торговая площадка | B36: =COUNTIF('Торговые точки'!$E$2:$E$846,A36) -> 29
A37: Минимаркет | B37: =COUNTIF('Торговые точки'!$E$2:$E$846,A37) -> 26
A38: Овощи/фрукты | B38: =COUNTIF('Торговые точки'!$E$2:$E$846,A38) -> 2
A39: Другой прикассовый формат | B39: =COUNTIF('Торговые точки'!$E$2:$E$846,A39) -> 2
A40: Гипермаркет | B40: =COUNTIF('Торговые точки'!$E$2:$E$846,A40) -> 1
A41: Киоск | B41: =COUNTIF('Торговые точки'!$E$2:$E$846,A41) -> 1

Sheet Торговые точки
A1: ID | B1: Компания / сеть | C1: Название точки | D1: Принадлежность к сети | E1: Тип | F1: Адрес | G1: Район | H1: Телефон | I1: Сайт / Instagram | J1: Известно филиалов | K1: Широта | L1: Долгота | M1: Основной источник | N1: Доп. источники | O1: Набор данных | P1: Дата проверки | Q1: Уверенность | R1: Прикассовое соответствие | S1: Примечание
A2: SHY-0001 | B2: Абдурахман | C2: Абдурахман | D2: Не установлено | E2: Магазин у дома / convenience | F2: мкр. Север | K2: 42.345683 | L2: 69.645043 | M2: https://www.openstreetmap.org/node/4490047993 | O2: OpenStreetMap | P2: 2026-08-11 | Q2: medium | R2: high | S2: именованная OSM-точка с дополнительными контактными или адресными полями
A3: SHY-0002 | B3: Абзал | C3: Абзал | D3: Не установлено | E3: Магазин у дома / convenience | K3: 42.305654 | L3: 69.624596 | M3: https://www.openstreetmap.org/node/1532793171 | O3: OpenStreetMap | P3: 2026-08-11 | Q3: medium | R3: high | S3: именованная OSM-точка в административной границе города
A4: SHY-0003 | B4: Адем | C4: Адем | D4: Не установлено | E4: Магазин у дома / convenience | K4: 42.3375 | L4: 69.65251 | M4: https://www.openstreetmap.org/node/1455157590 | O4: OpenStreetMap | P4: 2026-08-11 | Q4: medium | R4: high | S4: именованная OSM-точка в административной границе города
A5: SHY-0004 | B5: Азамат | C5: Азамат | D5: Возможная сеть: Азамат | E5: Магазин у дома / convenience | F5: мкр. Восток, 93 | K5: 42.334199 | L5: 69.646667 | M5: https://www.openstreetmap.org/node/4432254825 | O5: OpenStreetMap | P5: 2026-08-11 | Q5: medium | R5: high | S5: именованная OSM-точка с дополнительными контактными или адресными полями
A6: SHY-0005 | B6: Азиз | C6: Азиз | D6: Не установлено | E6: Магазин у дома / convenience | K6: 42.312662 | L6: 69.585053 | M6: https://www.openstreetmap.org/node/1458412965 | O6: OpenStreetMap | P6: 2026-08-11 | Q6: medium | R6: high | S6: именованная OSM-точка в административной границе города
A7: SHY-0006 | B7: Азық түлік | C7: Азық түлік | D7: Азық түлік | E7: Магазин у дома / convenience | F7: улица Айбергенова, 7 | K7: 42.314283 | L7: 69.581917 | M7: https://www.openstreetmap.org/node/4440164990 | O7: OpenStreetMap | P7: 2026-08-11 | Q7: medium | R7: high | S7: именованная OSM-точка с дополнительными контактными или адресными полями
A8: SHY-0007 | B8: Азық түлік | C8: Азық түлік | D8: Азық түлік | E8: Магазин у дома / convenience | F8: улица Торекулова, 216 | K8: 42.317153 | L8: 69.639147 | M8: https://www.openstreetmap.org/node/4785590321 | O8: OpenStreetMap | P8: 2026-08-11 | Q8: medium | R8: high | S8: именованная OSM-точка с дополнительными контактными или адресными полями
A9: SHY-0008 | B9: Азық түлік | C9: Азық түлік | D9: Азық түлік | E9: Магазин у дома / convenience | K9: 42.34415 | L9: 69.64181 | M9: https://www.openstreetmap.org/node/4490046492 | O9: OpenStreetMap | P9: 2026-08-11 | Q9: medium | R9: high | S9: именованная OSM-точка в административной границе города
A10: SHY-0009 | B10: Аида | C10: Аида | D10: Не установлено | E10: Магазин у дома / convenience | F10: улица Фабрициус, 17 | K10: 42.336543 | L10: 69.574197 | M10: https://www.openstreetmap.org/node/4782402623 | O10: OpenStreetMap | P10: 2026-08-11 | Q10: medium | R10: high | S10: именованная OSM-точка с дополнительными контактными или адресными полями
A11: SHY-0010 | B11: Ай ару | C11: Ай ару | D11: Возможная сеть: Ай ару | E11: Магазин у дома / convenience | K11: 42.313823 | L11: 69.578768 | M11: https://www.openstreetmap.org/node/4487902689 | O11: OpenStreetMap | P11: 2026-08-11 | Q11: medium | R11: high | S11: именованная OSM-точка в административной границе города
A12: SHY-0011 | B12: Ай-Асыл | C12: Ай-Асыл | D12: Не установлено | E12: Магазин у дома / convenience | F12: улица М.Дулати | K12: 42.333481 | L12: 69.607886 | M12: https://www.openstreetmap.org/node/4435449592 | O12: OpenStreetMap | P12: 2026-08-11 | Q12: medium | R12: high | S12: именованная OSM-точка с дополнительными контактными или адресными полями
A13: SHY-0012 | B13: Айбек | C13: Айбек | D13: Не установлено | E13: Магазин у дома / convenience | F13: мкр. Север, 44 | K13: 42.344196 | L13: 69.639933 | M13: https://www.openstreetmap.org/node/4490076695 | O13: OpenStreetMap | P13: 2026-08-11 | Q13: medium | R13: high | S13: именованная OSM-точка с дополнительными контактными или адресными полями
A14: SHY-0013 | B14: Айгуль | C14: Айгуль | D14: Не установлено | E14: Магазин у дома / convenience | F14: мкр. Север, 1 | K14: 42.339282 | L14: 69.639149 | M14: https://www.openstreetmap.org/node/4490084490 | O14: OpenStreetMap | P14: 2026-08-11 | Q14: medium | R14: high | S14: именованная OSM-точка с дополнительными контактными или адресными полями
A15: SHY-0014 | B15: Айда | C15: Айда | D15: Не установлено | E15: Магазин у дома / convenience | K15: 42.392876 | L15: 69.573055 | M15: https://www.openstreetmap.org/node/4885388121 | O15: OpenStreetMap | P15: 2026-08-11 | Q15: medium | R15: high | S15: именованная OSM-точка в административной границе города
A16: SHY-0015 | B16: Айдын | C16: Айдын | D16: Не установлено | E16: Магазин у дома / convenience | K16: 42.277752 | L16: 69.593372 | M16: https://www.openstreetmap.org/node/1473223196 | O16: OpenStreetMap | P16: 2026-08-11 | Q16: medium | R16: high | S16: именованная OSM-точка в административной границе города
A17: SHY-0016 | B17: Айзере | C17: Айзере | D17: Не установлено | E17: Магазин у дома / convenience | K17: 42.406147 | L17: 69.561701 | M17: https://www.openstreetmap.org/node/4788028724 | O17: OpenStreetMap | P17: 2026-08-11 | Q17: medium | R17: high | S17: именованная OSM-точка в административной границе города
A18: SHY-0017 | B18: Айнаш | C18: Айнаш | D18: Не установлено | E18: Магазин у дома / convenience | K18: 42.355813 | L18: 69.714943 | M18: https://www.openstreetmap.org/node/1506284777 | O18: OpenStreetMap | P18: 2026-08-11 | Q18: medium | R18: high | S18: именованная OSM-точка в административной границе города
A19: SHY-0018 | B19: Айнур | C19: Айнур | D19: Не установлено | E19: Магазин у дома / convenience | K19: 42.308702 | L19: 69.58051 | M19: https://www.openstreetmap.org/node/4546179893 | O19: OpenStreetMap | P19: 2026-08-11 | Q19: medium | R19: high | S19: именованная OSM-точка в административной границе города
A20: SHY-0019 | B20: Айсулан | C20: Айсулан | D20: Не установлено | E20: Магазин у дома / convenience | K20: 42.310501 | L20: 69.598284 | M20: https://www.openstreetmap.org/node/1458412967 | O20: OpenStreetMap | P20: 2026-08-11 | Q20: medium | R20: high | S20: именованная OSM-точка в административной границе города
A21: SHY-0020 | B21: Ак Жол | C21: Ак Жол | D21: Не установлено | E21: Магазин у дома / convenience | K21: 42.29871 | L21: 69.61727 | M21: https://www.openstreetmap.org/node/1458043947 | O21: OpenStreetMap | P21: 2026-08-11 | Q21: medium | R21: high | S21: именованная OSM-точка в административной границе города
A22: SHY-0021 | B22: Ак ниет | C22: Ак ниет | D22: Возможная сеть: Ак ниет | E22: Магазин у дома / convenience | F22: улица Диваева | K22: 42.333222 | L22: 69.613036 | M22: https://www.openstreetmap.org/node/4433680391 | O22: OpenStreetMap | P22: 2026-08-11 | Q22: medium | R22: high | S22: именованная OSM-точка с дополнительными контактными или адресными полями
A23: SHY-0022 | B23: Ак Орда | C23: Ак Орда | D23: Не установлено | E23: Магазин у дома / convenience | F23: улица Байтурсынова | K23: 42.342922 | L23: 69.604185 | M23: https://www.openstreetmap.org/node/4646679693 | O23: OpenStreetMap | P23: 2026-08-11 | Q23: medium | R23: high | S23: именованная OSM-точка с дополнительными контактными или адресными полями
A24: SHY-0023 | B24: Акерке | C24: Акерке | D24: Не установлено | E24: Магазин у дома / convenience | F24: мкр. Восток, 41А | K24: 42.338638 | L24: 69.643739 | M24: https://www.openstreetmap.org/node/4430223992 | O24: OpenStreetMap | P24: 2026-08-11 | Q24: medium | R24: high | S24: именованная OSM-точка с дополнительными контактными или адресными полями
A25: SHY-0024 | B25: Актай | C25: Актай | D25: Не установлено | E25: Магазин у дома / convenience | F25: Капал батыра | K25: 42.437311 | L25: 69.544221 | M25: https://www.openstreetmap.org/way/995451702 | O25: OpenStreetMap | P25: 2026-08-11 | Q25: medium | R25: high | S25: именованная OSM-точка с дополнительными контактными или адресными полями
A26: SHY-0025 | B26: Ақ Дастархан | C26: Ақ Дастархан | D26: Не установлено | E26: Магазин у дома / convenience | K26: 42.341515 | L26: 69.644166 | M26: https://www.openstreetmap.org/node/4782708021 | O26: OpenStreetMap | P26: 2026-08-11 | Q26: medium | R26: high | S26: именованная OSM-точка в административной границе города
A27: SHY-0026 | B27: Ақ жарқын | C27: Ақ жарқын | D27: Не установлено | E27: Магазин у дома / convenience | F27: улица Елшибек батыра | K27: 42.319543 | L27: 69.633246 | M27: https://www.openstreetmap.org/node/4785646722 | O27: OpenStreetMap | P27: 2026-08-11 | Q27: medium | R27: high | S27: именованная OSM-точка с дополнительными контактными или адресными полями
A28: SHY-0027 | B28: Ақ Кеме | C28: Ақ Кеме | D28: Не установлено | E28: Магазин у дома / convenience | K28: 42.38211 | L28: 69.646892 | M28: https://www.openstreetmap.org/node/12979577347 | O28: OpenStreetMap | P28: 2026-08-11 | Q28: medium | R28: high | S28: именованная OSM-точка в административной границе города
A29: SHY-0028 | B29: АҚжайық | C29: АҚжайық | D29: Не установлено | E29: Магазин у дома / convenience | F29: улица Сырым батыра | K29: 42.388224 | L29: 69.600168 | M29: https://www.openstreetmap.org/node/4885348722 | O29: OpenStreetMap | P29: 2026-08-11 | Q29: medium | R29: high | S29: именованная OSM-точка с дополнительными контактными или адресными полями
A30: SHY-0029 | B30: Алди | C30: Алди | D30: Не установлено | E30: Магазин у дома / convenience | K30: 42.308711 | L30: 69.585163 | M30: https://www.openstreetmap.org/node/12960596943 | O30: OpenStreetMap | P30: 2026-08-11 | Q30: medium | R30: high | S30: именованная OSM-точка в административной границе города
A31: SHY-0030 | B31: Алем | C31: Алем | D31: Алем | E31: Магазин у дома / convenience | K31: 42.313 | L31: 69.620533 | M31: https://www.openstreetmap.org/node/1455157614 | O31: OpenStreetMap | P31: 2026-08-11 | Q31: medium | R31: high | S31: именованная OSM-точка в административной границе города
A32: SHY-0031 | B32: Алем маркет | C32: Алем маркет | D32: Алем маркет | E32: Магазин у дома / convenience | K32: 42.38203 | L32: 69.647248 | M32: https://www.openstreetmap.org/node/12979577348 | O32: OpenStreetMap | P32: 2026-08-11 | Q32: medium | R32: high | S32: именованная OSM-точка в административной границе города
A33: SHY-0032 | B33: Алина | C33: Алина | D33: Не установлено | E33: Магазин у дома / convenience | K33: 42.310149 | L33: 69.641901 | M33: https://www.openstreetmap.org/node/1455157622 | O33: OpenStreetMap | P33: 2026-08-11 | Q33: medium | R33: high | S33: именованная OSM-точка в административной границе города
A34: SHY-0033 | B34: Алия | C34: Алия | D34: Не установлено | E34: Магазин у дома / convenience | K34: 42.346483 | L34: 69.617966 | M34: https://www.openstreetmap.org/node/4467229191 | O34: OpenStreetMap | P34: 2026-08-11 | Q34: medium | R34: high | S34: именованная OSM-точка в административной границе города
A35: SHY-0034 | B35: Алтай | C35: Алтай | D35: Алтай | E35: Магазин у дома / convenience | F35: Сурикова | K35: 42.299563 | L35: 69.58244 | M35: https://www.openstreetmap.org/node/5220165328 | O35: OpenStreetMap | P35: 2026-08-11 | Q35: medium | R35: high | S35: именованная OSM-точка с дополнительными контактными или адресными полями
A36: SHY-0035 | B36: Алтын ана | C36: Алтын ана | D36: Не установлено | E36: Магазин у дома / convenience | F36: Сайрамская улица, 46 | K36: 42.308477 | L36: 69.641669 | M36: https://www.openstreetmap.org/node/4483264591 | O36: OpenStreetMap | P36: 2026-08-11 | Q36: medium | R36: high | S36: именованная OSM-точка с дополнительными контактными или адресными полями
A37: SHY-0036 | B37: Алтын жулдыз | C37: Алтын жулдыз | D37: Не установлено | E37: Магазин у дома / convenience | K37: 42.303118 | L37: 69.588775 | M37: https://www.openstreetmap.org/node/1458043949 | O37: OpenStreetMap | P37: 2026-08-11 | Q37: medium | R37: high | S37: именованная OSM-точка в административной границе города
A38: SHY-0037 | B38: Алтын куз | C38: Алтын куз | D38: Не установлено | E38: Магазин у дома / convenience | F38: улица Аскарова | K38: 42.317685 | L38: 69.58057 | M38: https://www.openstreetmap.org/node/4437279190 | O38: OpenStreetMap | P38: 2026-08-11 | Q38: medium | R38: high | S38: именованная OSM-точка с дополнительными контактными или адресными полями
A39: SHY-0038 | B39: Алуа | C39: Алуа | D39: Не установлено | E39: Магазин у дома / convenience | K39: 42.34034 | L39: 69.611958 | M39: https://www.openstreetmap.org/node/4508776089 | O39: OpenStreetMap | P39: 2026-08-11 | Q39: medium | R39: high | S39: именованная OSM-точка в административной границе города
A40: SHY-0039 | B40: Анар | C40: Анар | D40: Анар | E40: Магазин у дома / convenience | F40: мкр. Север | K40: 42.340938 | L40: 69.638526 | M40: https://www.openstreetmap.org/node/1260468108 | O40: OpenStreetMap | P40: 2026-08-11 | Q40: medium | R40: high | S40: именованная OSM-точка с дополнительными контактными или адресными полями
...

Sheet Компании и сети
A1: Ключ организации | B1: Компания / бренд | C1: Статус объединения | D1: Точек в именной базе | E1: Известно филиалов | F1: Форматы | G1: Районы | H1: Телефоны | I1: Сайт / соцсети | J1: Источники | K1: Дата проверки | L1: Комментарий
A2: ind:SHY-0001 | B2: Абдурахман | C2: Независимая / не установлено | D2: 1 | F2: Магазин у дома / convenience | J2: https://www.openstreetmap.org/node/4490047993 | K2: 2026-08-11
A3: ind:SHY-0002 | B3: Абзал | C3: Независимая / не установлено | D3: 1 | F3: Магазин у дома / convenience | J3: https://www.openstreetmap.org/node/1532793171 | K3: 2026-08-11
A4: ind:SHY-0003 | B4: Адем | C4: Независимая / не установлено | D4: 1 | F4: Магазин у дома / convenience | J4: https://www.openstreetmap.org/node/1455157590 | K4: 2026-08-11
A5: brand:азамат | B5: Азамат | C5: Возможная сеть / одинаковое название | D5: 2 | F5: Магазин у дома / convenience, Супермаркет | G5: Туран | H5: +77476571712 | J5: https://www.openstreetmap.org/node/4432254825 | https://2gis.kz/shymkent/firm/70000001026566591 | https://2gis.kz/shymkent/search/%D0%A1%D1%83%D0%BF%D0%B5%D1%80%D0%BC%D0%B0%D1%80%D0%BA%D0%B5%D1%82%D1%8B%2C%20%D1%83%D0%BD%D0%B8%D0%B2%D0%B5%D1%80%D1%81%D0%B0%D0%BC%D1%8B%2C%20%D0%BC%D0%B8%D0%BD%D0%B8-%D0%BC%D0%B0%D1%80%D0%BA%D0%B5%D1%82%D1%8B/filters/district_id%3D70030076572844920/page/4 | K5: 2026-08-11 | L5: Требуется подтверждение единого владельца/закупки
A6: ind:SHY-0005 | B6: Азиз | C6: Независимая / не установлено | D6: 1 | F6: Магазин у дома / convenience | J6: https://www.openstreetmap.org/node/1458412965 | K6: 2026-08-11
A7: brand:азықтүлік | B7: Азық түлік | C7: Сеть (подтверждено) | D7: 3 | F7: Магазин у дома / convenience | J7: https://www.openstreetmap.org/node/4440164990 | https://www.openstreetmap.org/node/4785590321 | https://www.openstreetmap.org/node/4490046492 | K7: 2026-08-11
A8: ind:SHY-0009 | B8: Аида | C8: Независимая / не установлено | D8: 1 | F8: Магазин у дома / convenience | J8: https://www.openstreetmap.org/node/4782402623 | K8: 2026-08-11
A9: brand:айару | B9: Ай ару | C9: Возможная сеть / одинаковое название | D9: 2 | F9: Магазин у дома / convenience, Супермаркет | G9: Абайский | H9: +77078728682 | J9: https://www.openstreetmap.org/node/4487902689 | https://2gis.kz/shymkent/firm/70000001035570845 | https://2gis.kz/shymkent/search/%D0%A1%D1%83%D0%BF%D0%B5%D1%80%D0%BC%D0%B0%D1%80%D0%BA%D0%B5%D1%82%D1%8B%2C%20%D1%83%D0%BD%D0%B8%D0%B2%D0%B5%D1%80%D1%81%D0%B0%D0%BC%D1%8B%2C%20%D0%BC%D0%B8%D0%BD%D0%B8-%D0%BC%D0%B0%D1%80%D0%BA%D0%B5%D1%82%D1%8B/filters/district_id%3D22659345553271441/page/4 | K9: 2026-08-11 | L9: Требуется подтверждение единого владельца/закупки
A10: ind:SHY-0011 | B10: Ай-Асыл | C10: Независимая / не установлено | D10: 1 | F10: Магазин у дома / convenience | J10: https://www.openstreetmap.org/node/4435449592 | K10: 2026-08-11
A11: ind:SHY-0012 | B11: Айбек | C11: Независимая / не установлено | D11: 1 | F11: Магазин у дома / convenience | J11: https://www.openstreetmap.org/node/4490076695 | K11: 2026-08-11
A12: ind:SHY-0013 | B12: Айгуль | C12: Независимая / не установлено | D12: 1 | F12: Магазин у дома / convenience | J12: https://www.openstreetmap.org/node/4490084490 | K12: 2026-08-11
A13: ind:SHY-0014 | B13: Айда | C13: Независимая / не установлено | D13: 1 | F13: Магазин у дома / convenience | J13: https://www.openstreetmap.org/node/4885388121 | K13: 2026-08-11
A14: ind:SHY-0015 | B14: Айдын | C14: Независимая / не установлено | D14: 1 | F14: Магазин у дома / convenience | J14: https://www.openstreetmap.org/node/1473223196 | K14: 2026-08-11
A15: ind:SHY-0016 | B15: Айзере | C15: Независимая / не установлено | D15: 1 | F15: Магазин у дома / convenience | J15: https://www.openstreetmap.org/node/4788028724 | K15: 2026-08-11
A16: ind:SHY-0017 | B16: Айнаш | C16: Независимая / не установлено | D16: 1 | F16: Магазин у дома / convenience | J16: https://www.openstreetmap.org/node/1506284777 | K16: 2026-08-11
A17: ind:SHY-0018 | B17: Айнур | C17: Независимая / не установлено | D17: 1 | F17: Магазин у дома / convenience | J17: https://www.openstreetmap.org/node/4546179893 | K17: 2026-08-11
A18: ind:SHY-0019 | B18: Айсулан | C18: Независимая / не установлено | D18: 1 | F18: Магазин у дома / convenience | J18: https://www.openstreetmap.org/node/1458412967 | K18: 2026-08-11
A19: ind:SHY-0020 | B19: Ак Жол | C19: Независимая / не установлено | D19: 1 | F19: Магазин у дома / convenience | J19: https://www.openstreetmap.org/node/1458043947 | K19: 2026-08-11
A20: brand:акниет | B20: Ак ниет | C20: Возможная сеть / одинаковое название | D20: 2 | E20: 1 | F20: Магазин у дома / convenience, Рынок / торговая площадка | H20: +77074654741 | J20: https://www.openstreetmap.org/node/4433680391 | https://2gis.kz/shymkent/firm/70000001062730082 | K20: 2026-08-11 | L20: Требуется подтверждение единого владельца/закупки
A21: ind:SHY-0022 | B21: Ак Орда | C21: Независимая / не установлено | D21: 1 | F21: Магазин у дома / convenience | J21: https://www.openstreetmap.org/node/4646679693 | K21: 2026-08-11
A22: ind:SHY-0023 | B22: Акерке | C22: Независимая / не установлено | D22: 1 | F22: Магазин у дома / convenience | J22: https://www.openstreetmap.org/node/4430223992 | K22: 2026-08-11
A23: ind:SHY-0024 | B23: Актай | C23: Независимая / не установлено | D23: 1 | F23: Магазин у дома / convenience | J23: https://www.openstreetmap.org/way/995451702 | K23: 2026-08-11
A24: ind:SHY-0025 | B24: Ақ Дастархан | C24: Независимая / не установлено | D24: 1 | F24: Магазин у дома / convenience | J24: https://www.openstreetmap.org/node/4782708021 | K24: 2026-08-11
A25: ind:SHY-0026 | B25: Ақ жарқын | C25: Независимая / не установлено | D25: 1 | F25: Магазин у дома / convenience | J25: https://www.openstreetmap.org/node/4785646722 | K25: 2026-08-11
A26: ind:SHY-0027 | B26: Ақ Кеме | C26: Независимая / не установлено | D26: 1 | F26: Магазин у дома / convenience | J26: https://www.openstreetmap.org/node/12979577347 | K26: 2026-08-11
A27: ind:SHY-0028 | B27: АҚжайық | C27: Независимая / не установлено | D27: 1 | F27: Магазин у дома / convenience | J27: https://www.openstreetmap.org/node/4885348722 | K27: 2026-08-11
A28: ind:SHY-0029 | B28: Алди | C28: Независимая / не установлено | D28: 1 | F28: Магазин у дома / convenience | J28: https://www.openstreetmap.org/node/12960596943 | K28: 2026-08-11
A29: brand:алем | B29: Алем | C29: Сеть (подтверждено) | D29: 1 | F29: Магазин у дома / convenience | J29: https://www.openstreetmap.org/node/1455157614 | K29: 2026-08-11
A30: brand:алеммаркет | B30: Алем маркет | C30: Сеть (подтверждено) | D30: 1 | F30: Магазин у дома / convenience | J30: https://www.openstreetmap.org/node/12979577348 | K30: 2026-08-11
A31: ind:SHY-0032 | B31: Алина | C31: Независимая / не установлено | D31: 1 | F31: Магазин у дома / convenience | J31: https://www.openstreetmap.org/node/1455157622 | K31: 2026-08-11
A32: ind:SHY-0033 | B32: Алия | C32: Независимая / не установлено | D32: 1 | F32: Магазин у дома / convenience | J32: https://www.openstreetmap.org/node/4467229191 | K32: 2026-08-11
... A40: ind:SHY-0042 | B40: Аңсар | C40: Независимая / не установлено | D40: 1 | F40: Магазин у дома / convenience | J40: https://www.openstreetmap.org/node/4788091423 | K40: 2026-08-11
A41: brand:арай | B41: Арай | C41: Сеть (подтверждено) | D41: 3 | F41: Магазин у дома / convenience, Продуктовый магазин | G41: Абайский | H41: +77055680214 | J41: https://www.openstreetmap.org/node/4789381921 | https://www.openstreetmap.org/node/4516585190 | https://2gis.kz/shymkent/firm/70000001083272014 | https://2gis.kz/shymkent/search/%D0%A1%D1%83%D0%BF%D0%B5%D1%80%D0%BC%D0%B0%D1%80%D0%BA%D0%B5%D1%82%D1%8B%2C%20%D1%83%D0%BD%D0%B8%D0%B2%D0%B5%D1%80%D1%81%D0%B0%D0%BC%D1%8B%2C%20%D0%BC%D0%B8%D0%BD%D0%B8-%D0%BC%D0%B0%D1%80%D0%BA%D0%B5%D1%82%D1%8B/filters/district_id%3D22659345553271441/page/5 | K41: 2026-08-11
A42: ind:SHY-0045 | B42: Арайлым | C42: Независимая / не установлено | D42: 1 | F42: Магазин у дома / convenience | J42: https://www.openstreetmap.org/node/4859722521 | K42: 2026-08-11
A43: brand:арзан | B43: Арзан | C43: Сеть (подтверждено) | D43: 5 | F43: Магазин у дома / convenience, Супермаркет, Продуктовый магазин | G43: Абайский, Туран, Енбекшинский | H43: +77053320232, +77087207180, +77780010770 | J43: https://www.openstreetmap.org/node/12964522579 | https://www.openstreetmap.org/node/4782466522 | https://www.openstreetmap.org/node/3728571231 | https://2gis.kz/shymkent/firm/70000001082669321 | https://2gis.kz/shymkent/search/%D0%A1%D1%83%D0%BF%D0%B5%D1%80%D0%BC%D0%B0%D1%80%D0%BA%D0%B5%D1%82%D1%8B%2C%20%D1%83%D0%BD%D0%B8%D0%B2%D0%B5%D1%80%D1%81%D0%B0%D0%BC%D1%8B%2C%20%D0%BC%D0%B8%D0%BD%D0%B8-%D0%BC%D0%B0%D1%80%D0%BA%D0%B5%D1%82%D1%8B/filters/district_id%3D22659345553271441/page/4 | https://2gis.kz/shymkent/firm/70000001060675607 | https://2gis.kz/shymkent/search/%D0%A1%D1%83%D0%BF%D0%B5%D1%80%D0%BC%D0%B0%D1%80%D0%BA%D0%B5%D1%82%D1%8B%2C%20%D1%83%D0%BD%D0%B8%D0%B2%D0%B5%D1%80%D1%81%D0%B0%D0%BC%D1%8B%2C%20%D0%BC%D0%B8%D0%BD%D0%B8-%D0%BC%D0%B0%D1%80%D0%BA%D0%B5%D1%82%D1%8B/filters/district_id%3D70030076572844920/page/3 | https://2gis.kz/shymkent/firm/70000001099381542 | https://2gis.kz/shymkent/search/%D0%A1%D1%83%D0%BF%D0%B5%D1%80%D0%BC%D0%B0%D1%80%D0%BA%D0%B5%D1%82%D1%8B%2C%20%D1%83%D0%BD%D0%B8%D0%B2%D0%B5%D1%80%D1%81%D0%B0%D0%BC%D1%8B%2C%20%D0%BC%D0%B8%D0%BD%D0%B8-%D0%BC%D0%B0%D1%80%D0%BA%D0%B5%D1%82%D1%8B/filters/district_id%3D22659345553272097/page/2 | K43: 2026-08-11
A44: ind:SHY-0048 | B44: Арзан 2 | C44: Независимая / не установлено | D44: 1 | F44: Магазин у дома / convenience | J44: https://www.openstreetmap.org/node/4814918121 | K44: 2026-08-11
A45: ind:SHY-0049 | B45: Арзан пожарка | C45: Независимая / не установлено | D45: 1 | F45: Магазин у дома / convenience | J45: https://www.openstreetmap.org/node/4788085921 | K45: 2026-08-11
A46: ind:SHY-0050 | B46: Арпакуль ана | C46: Независимая / не установлено | D46: 1 | F46: Магазин у дома / convenience | J46: https://www.openstreetmap.org/node/4430223991 | K46: 2026-08-11
A47: ind:SHY-0051 | B47: Арсен | C47: Независимая / не установлено | D47: 1 | F47: Магазин у дома / convenience | J47: https://www.openstreetmap.org/node/4467263589 | K47: 2026-08-11
...

Sheet Дилеры
A1: ID | B1: Дилер | C1: Юр. название | D1: Рейтинг | E1: Топ-10 | F1: Почему в топ-10 | G1: Общая пригодность | H1: Склад | I1: Доставка | J1: FMCG-дистрибуция | K1: Сеть торговых точек | L1: Торговые представители | M1: Адрес / склад Шымкент | N1: Телефон | O1: Email | P1: Сайт | Q1: Соцсети | R1: Категории | S1: Бренды | T1: Доказательство склада | U1: Доказательство доставки | V1: Доказательство ТП | W1: География | X1: Охват / точки | Y1: Численные claims | Z1: Что неизвестно | AA1: Источники | AB1: Дата проверки
A2: beverage_trade_fbs | B2: Beverage Trade / FBS Group | C2: ТОО BEVERAGE TRADE | D2: A | E2: 1 | F2: Самый прозрачный локальный охват: южный хаб, склад 8 000 м² и 4 400 активных точек в четырёх южных городах; для Шымкента отдельно ранее раскрывалось 2 971. | G2: Очень сильный региональный кандидат для напитков и импульсной розницы: южный логистический хаб, традиционная розница, собственная сеть мини-маркетов. | H2: Да | I2: Да | J2: Да | K2: Да | L2: Да | M2: Шымкент, Каратауский район, жилой массив Тассай, квартал 119, здание 4969/8 | N2: +7 700 090 00 22 | O2: info@fbs-group.kz | P2: https://fbs-group.kz/divisions/too-beverage-trade | R2: вода, лимонады, энергетические и газированные напитки, напитки для HoReCa | T2: Компания заявляет склад 8 000 м²; локальная принадлежность к южному хабу указана на корпоративном сайте. | U2: Прямая доставка и собственная логистика заявлены группой. | V2: Наличие полевой команды следует из модели прямой дистрибуции, но численность по Шымкенту не раскрыта. | W2: Шымкент, Туркестан, Сарыагаш, Жетысай | X2: Показатели раскрыты только совокупно по четырём южным городам, не по Шымкенту отдельно. | Y2: active_outlets_four_cities: 4400; market_coverage_percent_claim: 95; warehouse_sqm: 8000; group_active_outlets: 12000; group_vehicles: 158 | Z2: число активных точек именно в Шымкенте; минимальный заказ и отсрочка платежа; свободна ли категория требуемого бренда; частота визитов торговых представителей | AA2: https://fbs-group.kz/divisions/too-beverage-trade | https://fbs-group.kz/ | AB2: 2026-08-11
A3: dudar | B3: Dudar | C3: ТОО «Дудар» | D3: A | E3: 2 | F3: 18 складов, собственная доставка за 24 часа, полевые coverage-планы и клиентская база от магазинов до АЗС. | G3: Национальный FMCG-дистрибьютор с филиалом в Шымкенте, собственными складами, доставкой и полевой командой. | H3: Да | I3: Да | J3: Да | K3: Да | L3: Да | M3: Шымкент, ул. Аймауытова, 143 (карточка 2GIS; подтвердить перед визитом) | N3: +7 701 027-83-47 | P3: https://dudar.kz/ru/main | R3: продовольственный и непродовольственный FMCG, кондитерские изделия, детское питание, гигиена | S3: Ritter Sport, Ярмарка, Черноголовка, Nutrilak | T3: 18 складов по Казахстану; температурные режимы. | U3: Собственный транспорт, доставка в течение 24 часов по заявлению компании. | V3: Торговые силы, coverage-планы и master-листы подтверждены официально. | W3: Все регионы Казахстана; локальная карточка Шымкента. | X3: Более 29 500 клиентов: традиционная розница, сети, АЗС и HoReCa. | Y3: warehouses: 18; clients_more_than: 29500 | Z3: локальный размер склада; число клиентов только в Шымкенте | AA3: https://dudar.kz/ru/services | https://dudar.kz/ru/clients | https://2gis.kz/shymkent/firm/70000001052262635/tab/info | AB3: 2026-08-11
A4: prima_distribution | B4: Prima Distribution | C4: ТОО Prima Distribution | D4: A | E4: 3 | F4: Филиал и прямой контакт в Шымкенте; 35 000+ точек по Казахстану, сильная торговая и мерчендайзинговая система. | G4: Крупный FMCG-дистрибьютор с прямым филиальным контактом в Шымкенте и сильным портфелем кондитерки/кофе. | H4: Да | I4: Да | J4: Да | K4: Да | L4: Да | M4: Шымкент, Сайрамское шоссе, 3 | N4: +7 777 005 73 00, 8 8000 80 80 81 | O4: shymkent@prima-group.kz, ya.prima-group@yandex.ru | P4: https://www.prima-group.kz/ | R4: кондитерские изделия, шоколад, жевательные конфеты, кофе, продукты питания, товары повседневного спроса | S4: Haribo, Storck, MacCoffee, Ferrero, Strauss | T4: Локальный адрес филиала подтверждён официальной страницей; тип и площадь помещения не раскрыты. | U4: Компания описывает дистрибуционный и логистический сервис, но локальные SLA не опубликованы. | V4: Торговая и мерчендайзинговая функция является частью официальной модели; локальная численность неизвестна. | W4: 34 города по заявлению компании; дополнительно есть южные филиалы в Сарыагаше, Атакенте, Туркестане и Таразе. | X4: Национально более 35 000 точек по корпоративному заявлению; Шымкент отдельно не раскрыт. | Y4: cities: 34; national_outlets_more_than: 35000 | Z4: локальная площадь склада; число локальных торговых представителей; локальный охват; свободные категории | AA4: https://www.prima-group.kz/ | https://www.prima-group.kz/kontakty/ | AB4: 2026-08-11
A5: apple_city_corps | B5: Apple City Corps | C5: Региональное представительство Apple City Corps — Шымкент | D5: A | E5: 4 | F5: 35 представительств, 27 000+ клиентов, собственные склады и автопарк; шымкентский филиал подтверждён. | G5: Крупный национальный FMCG-оператор с зарегистрированным региональным представительством, торговыми командами и собственной логистикой. | H5: Да | I5: Да | J5: Да | K5: Да | L5: Да | M5: Шымкент, Сайрамское шоссе, здание 3 | N5: +7 727 250 05 50 | O5: info@applecity.kz | P5: https://www.applecity.kz/ | R5: FMCG, продукты питания, напитки, товары у кассы — портфель нужно уточнить | T5: Компания заявляет терминалы и склады в каждом городе присутствия; площадь и адрес шымкентского склада отдельно не раскрыты. | U5: Собственный грузовой парк и полный цикл доставки заявлены компанией. | V5: Локальная торговая функция подтверждается региональным представительством и вакансиями; численность неизвестна. | W5: 35 региональных представительств по корпоративному заявлению; шымкентское представительство зарегистрировано с 2007 года. | X5: 27 000+ клиентов/точек относятся ко всей географии компании, не к Шымкенту. | Y5: regional_offices: 35; clients_more_than: 27000; warehouse_sqm_more_than: 100000; trucks: 376; cars: 532; brands_more_than: 80 | Z5: актуальный продуктовый портфель именно филиала; локальный склад и парк; локальный охват; прямой локальный закупочный контакт | AA5: https://www.applecity.kz/about | https://www.applecity.kz/contacts | https://kompra.kz/organization/070142012664 | AB5: 2026-08-11
A6: aspan_asia | B6: Aspan Asia | C6: ТОО Aspan Asia / южный филиал | D6: A | E6: 5 | F6: Сильный южный контур, собственные склады/доставка и релевантный импульсный портфель снеков, печенья и напитков. | G6: Южно-казахстанская FMCG-инфраструктура с портфелем Orion, Nongshim и Lotte Chilsung; заявлены каналы традиционной розницы, HoReCa и АЗС. | H6: Да | I6: Да | J6: Да | K6: Да | L6: Да | M6: Шымкент, проспект Жибек жолы, 64/6 | N6: +7 727 398 04 62, +7 777 191 01 11, +7 777 077 71 13 | O6: info@aspan-asia.kz, a.usenov@aspanasia.com, avkorenkova@aspan-asia.kz | P6: https://www.aspan-asia.kz/ | R6: Choco Pie и печенье, чипсы и крекеры, рамен и снеки, газировка, энергетики, холодный кофе и чай | S6: Orion, Nongshim, Lotte Chilsung, DoFood, Master Kan | T6: Компания заявляет собственные склады с температурными зонами по Южному Казахстану; площадь конкретно шымкентского объекта неизвестна. | U6: Компания заявляет собственную доставку до точки в каждом регионе присутствия. | V6: Свежая вакансия в Шымкенте подтверждает торгового представителя каналов B/C. | W6: Шымкент, Тараз, Туркестан, Кызылорда, Сарыагаш, другие регионы Казахстана и ЦА | X6: Подробные цифры на сайте относятся ко всему Казахстану, не к Шымкенту. | Y6: warehouses_sqm_south_kazakhstan: 87000; kazakhstan_trade_representatives: 570; kazakhstan_outlets_A: 450; kazakhstan_outlets_B_plus: 2250; kazakhstan_outlets_B_C: 31800; logistics_vehicles_conflict: 48,215 | Z6: локальная площадь склада; локальный парк; количество маршрутов и активных точек Шымкента; разница в определениях автопарка | AA6: https://www.aspan-asia.kz/ | https://shymkent.hh.kz/vacancies/torgovyj-predstavitel-po-razvitiyu-territorii/polniy_den | AB6: 2026-08-11
A7: alidi_kazakhstan | B7: ALIDI Kazakhstan | C7: ТОО АЛИДИ Казахстан | D7: A | E7: 6 | F7: Системный route-to-market, доставка MT/GT, локальные торговые представители и 16 000+ точек по Казахстану. | G7: Сильная национальная GT/MT-инфраструктура, доставка, мерчендайзинг и действующая команда Nestlé в Шымкенте. | H7: Да | I7: Да | J7: Да | K7: Да | L7: Да | M7: Свежие вакансии указывают ул. Сайрамская, 3; 2GIS отдельно показывает локальный складской центр — точный договорной адрес уточнить. | N7: 8 800 080 01 25 | O7: alidi.kz@alidi.com | P7: https://www.alidi.kz/ru/ | R7: продукты питания, детское питание, кондитерские и импульсные товары портфеля Nestlé, товары для животных | T7: Национальная складская инфраструктура подтверждается сайтом; площадь шымкентского центра не раскрыта. | U7: Официально заявлены доставка MT/GT/e-commerce, складская обработка и ответственное хранение. | V7: Свежие вакансии в Шымкенте подтверждают торгового представителя и супервайзера Nestlé. | W7: Казахстан; локальная активность Шымкента подтверждена вакансиями. | X7: Более 16 000 точек по Казахстану по заявлению компании; локальный охват неизвестен. | Y7: national_outlets_more_than: 16000; brands_more_than: 100; warehouse_sqm: 18200 | Z7: локальный охват; точный адрес и площадь шымкентского склада; доступность категорий вне действующих контрактов; локальный контакт закупок | AA7: https://www.alidi.kz/ru/ | https://www.alidi.kz/ru/services-ru/service-logistic-ru/ | https://shymkent.hh.kz/vacancies/torgovyj-predstavitel-fmcg/ot_pryamih_rabotodateley | AB7: 2026-08-11
A8: f_food | B8: F-Food | C8: ТОО F-Food | D8: A | E8: 7 | F8: Шымкентская база 2 500 м², кондитерка и снеки, доставка и действующая региональная дилерская сеть. | G8: Локальный складской дистрибьютор кондитерских и других импульсных товаров с прямыми иностранными контрактами. | H8: Да | I8: Да | J8: Да | K8: Да | L8: Неизвестно | M8: Шымкент, ул. Капал батыра, 4А | N8: +7 7252 98 21 52, +7 778 463 83 73 | P8: https://f-food.kz/ | R8: конфеты, печенье, шоколад, мармелад, попкорн, овсяные сладости | S8: Elvan, Komili / Mix&Max, Roshen | T8: На собственном сайте заявлена оптовая база и склад 2 500 м² с контролем влажности и температуры. | U8: 2GIS помечает доставку; условия и собственный транспорт публично не раскрыты. | W8: Компания заявляет дистрибуцию по Казахстану через региональных партнёров; локальный офис и база находятся в Шымкенте. | Y8: warehouse_sqm: 2500 | Z8: локальный охват; штат торговых представителей; парк доставки; актуальные эксклюзивные права; email отдела закупок | AA8: https://f-food.kz/ | https://2gis.kz/shymkent/search/F-Food | AB8: 2026-08-11
A9: bgt_company | B9: BGT Company | C9: ТОО «BGT Company» | D9: A | E9: 8 | F9: Локальная клиентская база 3 087, три склада и девять автомобилей — хороший кандидат для быстрого пилота. | G9: Локальный дистрибьютор с собственной базой, автопарком и заявленной клиентской сетью — удобен для быстрого пилота. | H9: Да | I9: Да | J9: Да | K9: Да | L9: Неизвестно | M9: Шымкент, ул. Рашидова, 14а/7 (актуальная карточка 2GIS) | O9: Biznes-17@mail.ru | P9: https://biznes-group.kz/ | R9: продукты быстрого приготовления, напитки, бакалея, соусы и консервация | S9: Big Lunch, Здравпродукт, Впрок, Kimono | T9: 3 операционных склада; 1 000 м² по заявлению компании. | U9: 9 автомобилей; 2GIS отмечает доставку. | V9: Действующая локальная дистрибуция; численность торговых представителей публично не раскрыта. | W9: Шымкент и региональный рынок. | X9: Заявленная общая клиентская база 3 087. | Y9: warehouses: 3; warehouse_sqm: 1000; vehicles: 9; clients: 3087 | Z9: актуальный прямой телефон; частота визитов и число активных точек в городе | AA9: https://biznes-group.kz/ | https://2gis.kz/shymkent/firm/70000001094744329 | AB9: 2026-08-11
A10: rg_brands | B10: RG Brands Kazakhstan | C10: Филиал ТОО RG Brands Kazakhstan в г. Шымкент | D10: A | E10: 9 | F10: Склад и торговая команда в Шымкенте, плотный охват напитков; ключевой риск — готовность брать внешний бренд. | G10: Собственная южная торговая ветка производителя напитков с действующими маршрутами по Шымкенту и Туркестанской области. | H10: Да | I10: Да | J10: Да | K10: Да | L10: Да | M10: Шымкент, Сайрамское шоссе, 3, БЦ «Бирлесу», 4 этаж | N10: +7 705 997 05 49 | O10: konstantin.melikhov@brands.kz | P10: https://www.rgbrands.com/ | R10: вода, соки, холодный чай, лимонады, энергетические напитки, молочные напитки | S10: A'SU, GRAZIO, PIALA, LAVINA, DA-DA, AVA | T10: Филиал и адрес подтверждены корпоративным контактным PDF и раскрытием KASE; площадь склада не опубликована. | U10: Собственная дистрибуционная ветка подтверждена структурой филиала; локальные SLA не раскрыты. | V10: Вакансии июля 2026 подтверждают торговых представителей и супервайзера по A'SU, GRAZIO, PIALA, LAVINA и DA-DA. | W10: Шымкент, Тюлькубас, Арыс, Бозарык, Карабулак, Ленгер | Z10: локальный охват; площадь и режим склада; условия работы с внешним брендом; канальная эксклюзивность | AA10: https://kase.kz/files/emitters/RGBK/rgbkf9_KZ2P00009970_290525_ru.pdf | https://api.rgbrands.com/uploads/0/1274-contacts_rgbrands.pdf | https://kz.joblum.com/company/rg-brands-kazakhstan | AB10: 2026-08-11
A11: star_brands_asia | B11: Star Brands Asia | C11: Star Brands Asia | D11: B | E11: 10 | F11: Импульсный портфель снеков и кондитерки, 21 филиал и локальный торговый представитель; требуется подтвердить склад и SLA. | G11: Лучшее прямое соответствие импульсной категории: чипсы, сухарики, орехи, попкорн, семечки, кондитерка и лапша; свежая вакансия торгового представителя в Шымкенте. | H11: Неизвестно | I11: Да | J11: Да | K11: Да | L11: Да | M11: Свежая вакансия указывает Сайрамское шоссе, 6а; в других карточках встречается дом 5 — уточнить до визита. | N11: +7 727 382 19 45 | O11: info-sba@sbasia.net | P11: https://starbrands-asia.kz/ | R11: чипсы, сухарики, арахис и фисташки, попкорн, семечки, кондитерские изделия, лапша быстрого приготовления, морепродукты-снеки | S11: Slang, Grizzly, Flint, Hroom, Big Bob, Jet, IZI Corn, Frumi, Noodles Master, Salam, ETI, Akulchev | U11: Национальная модель дистрибуции подтверждена сайтом; локальные SLA и транспорт не раскрыты. | V11: Наличие локального торгового представителя по кондитерскому направлению подтверждается вакансией, опубликованной 15.07.2026. | W11: 21 филиал по Казахстану по заявлению компании; локальная активность в Шымкенте подтверждена вакансией. | X11: Только национальная цифра, без выделения Шымкента. | Y11: kazakhstan_branches: 21; trade_representatives: 741; retail_outlets: 48989; snack_skus_more_than: 100 | Z11: локальный склад; точный локальный адрес; число маршрутов и точек Шымкента; условия нового контракта | AA11: https://starbrands-asia.kz/ | https://dreamjob.ru/employers/3240805/vakansii/135215027 | AB11: 2026-08-11
A12: altyn_alma_distribution | B12: Altyn Alma Distribution | C12: Филиал ТОО Altyn Alma Distribution в г. Шымкент, БИН 170341006206 | D12: B | G12: Сильный национальный FMCG-портфель; вакансия Ferrero до 10.08.2026 показывает недавнюю локальную коммерческую активность, но юридический статус филиала нужно перепроверить. | H12: Неизвестно | I12: Да | J12: Да | K12: Да | L12: Да | M12: Шымкент, ул. Акжиек, 168а — текущая карточка; в реестрах также встречается Байдибек би, 168. | N12: +7 771 553 25 13, +7 727 339 92 32 | O12: info@almadi.kz | P12: https://altyn-alma.kz/ | R12: шоколад и кондитерские изделия, напитки, молочные продукты, FMCG | S12: Ferrero, Mars, Red Bull, Ehrmann, Kellogg's — исторический/корпоративный портфель, актуальность по филиалу уточнить | T12: Компания заявляет 4 распределительных центра национально; локальный склад не подтверждён. | U12: Холодовая цепь и хранение заявлены национально; локальные SLA неизвестны. | V12: Вакансия торгового представителя отдела Ferrero опубликована 11.06.2026 и была действительна до 10.08.2026. | W12: Шымкент указан среди городов присутствия на сайте. | Y12: branches: 18; mini_branches: 19; distribution_centers: 4; employees_more_than: 4000 | Z12: действующая договорная сторона и БИН; локальный склад; локальный охват; прямой локальный контакт | AA12: https://altyn-alma.kz/ | https://shymkent.cataloxy-kz.ru/rabota/vacancy1067257329_torgovyy-predstavitel-kategorii-vs-otdela-ferrero.htm | https://2gis.kz/shymkent/geo/22659371323856310/tab/inside | https://kompra.kz/organization/170341006206 | https://zangazet.kz/wp-content/uploads/2025/10/zg2025-79.pdf | AB12: 2026-08-11
A13: asia_mr_plus | B13: AsiaMR+ | C13: На сайте — ТОО ASIA MR+; найденная близкая запись ТОО ASIA-MR, БИН 200840015226, требует подтверждения связи | D13: B | G13: Локальный южный дистрибьютор напитков и продуктов с заявленными складами и автопарком; особенно интересен для безалкогольных напитков. | H13: Да | I13: Да | J13: Да | K13: Неизвестно | L13: Неизвестно | M13: Шымкент, ул. Койкелди батыра, 3/5 | N13: +7 705 411 80 30 | O13: asia.distr@gmail.com | P13: https://asiadistribution.kz/ | R13: лимонады, морсы, компоты, безалкогольные напитки, консервация, кондитерские изделия по карточке 2GIS | S13: Очаково, Натуральные напитки, Green Ray, Царицынские соленья | T13: Сайт заявляет собственные логистические склады; 2GIS подтверждает локальную операционную карточку, но размер и право владения не раскрыты. | U13: 2GIS помечает доставку; сайт заявляет собственный автопарк. | V13: Сайт говорит о квалифицированном штате, но торговые представители и маршруты отдельно не подтверждены. | W13: Шымкент, Тараз, Алматы | Z13: точный БИН и договорная сторона; локальный охват; число торговых представителей; размер склада и автопарка; актуальность эксклюзивных прав | AA13: https://asiadistribution.kz/ | https://2gis.kz/shymkent/firm/70000001036552058/tab/info | https://ba.prg.kz/790000000-shymkent/200840015226-too-asia-mr-aziya-mr/ | AB13: 2026-08-11
A14: rich_life_distribution | B14: Rich Life Distribution | C14: ТОО Rich Life Distribution, БИН 100140009919 | D14: B | G14: Реальный локальный оптовик со складом в Шымкенте и заявленной доставкой по городу и Туркестанской области; есть снеки и напитки. | H14: Да | I14: Да | J14: Да | K14: Неизвестно | L14: Неизвестно | M14: Шымкент, ул. Капал батыра, 4А | N14: +7 700 720 53 05, +7 747 343 24 95 | O14: beshim93@mail.ru | P14: https://richlife.kz/ | R14: снеки, напитки и энергетики, бакалея, печенье, орехи, товары народного потребления | T14: Сайт заявляет офис и склад в Шымкенте; юридический адрес совпадает с Капал батыра, 4А. | U14: Сайт заявляет ежедневные отгрузки и доставку менее 48 часов по Шымкенту и Туркестанской области. | W14: Шымкент, Туркестанская область, 15 регионов по заявлению сайта | Y14: regions: 15; delivery_hours_less_than: 48; brands_more_than: 10; hit_skus_more_than: 120 | Z14: локальная площадь склада; автопарк; торговые представители; охват точек; актуальные права на бренды | AA14: https://richlife.kz/ | https://ba.prg.kz/790000000-shymkent/100140009919-too-rich-life-distribution/ | AB14: 2026-08-11
